Workbook
Name dob: #REF!
Name end: #REF!
Name sign: #REF!
Name start: #REF!
Name symbol: #REF!

Sheet Data
A1: Name | B1: Country | C1: Starting year | D1: End year | E1: Years active | F1: Birthdate | G1: Gender | H1: Zodiac sign | I1: Proven victims
A2: Luis Garavito | B2: Colombia | C2: 1992 | D2: 1999 | E2: =Table1[[#This Row],[End year]]-Table1[[#This Row],[Starting year]] -> 7 | F2: 20845 | G2: M | H2: =VLOOKUP(DATE(2023,MONTH(F2),DAY(F2)),Signs!A:C,3) -> Aquarius | I2: 193
A3: Pedro López | B3: Colombia | C3: 1969 | D3: 1979 | E3: =Table1[[#This Row],[End year]]-Table1[[#This Row],[Starting year]] -> 10 | F3: 17814 | G3: M | H3: =VLOOKUP(DATE(2023,MONTH(F3),DAY(F3)),Signs!A:C,3) -> Libra | I3: 110
A4: Miyuki Ishikawa | B4: Japan | C4: 1944 | D4: 1948 | E4: =Table1[[#This Row],[End year]]-Table1[[#This Row],[Starting year]] -> 4 | F4: Unknown | G4: F | H4: Unknown | I4: 103
A5: Javed Iqbal | B5: Pakistan | C5: 1998 | D5: 1999 | E5: =Table1[[#This Row],[End year]]-Table1[[#This Row],[Starting year]] -> 1 | F5: Unknown | G5: M | H5: Unknown | I5: 100
A6: Mikhail Popkov | B6: Russia | C6: 1992 | D6: 2010 | E6: =Table1[[#This Row],[End year]]-Table1[[#This Row],[Starting year]] -> 18 | F6: 23443 | G6: M | H6: =VLOOKUP(DATE(2023,MONTH(F6),DAY(F6)),Signs!A:C,3) -> Pisces | I6: 83
A7: Daniel Camargo Barbosa | B7: Colombia | C7: 1974 | D7: 1986 | E7: =Table1[[#This Row],[End year]]-Table1[[#This Row],[Starting year]] -> 12 | F7: 10980 | G7: M | H7: =VLOOKUP(DATE(2023,MONTH(F7),DAY(F7)),Signs!A:C,3) -> Aquarius | I7: 72
A8: Pedro Rodrigues Filho | B8: Brazil | C8: 1967 | D8: 2003 | E8: =Table1[[#This Row],[End year]]-Table1[[#This Row],[Starting year]] -> 36 | F8: 20026 | G8: M | H8: =VLOOKUP(DATE(2023,MONTH(F8),DAY(F8)),Signs!A:C,3) -> Scorpio | I8: 71
A9: Kampatimar Shankariya | B9: India | C9: 1977 | D9: 1978 | E9: =Table1[[#This Row],[End year]]-Table1[[#This Row],[Starting year]] -> 1 | F9: Unknown | G9: M | H9: Unknown | I9: 70
A10: Yang Xinhai | B10: China | C10: 2000 | D10: 2003 | E10: =Table1[[#This Row],[End year]]-Table1[[#This Row],[Starting year]] -> 3 | F10: 25036 | G10: M | H10: =VLOOKUP(DATE(2023,MONTH(F10),DAY(F10)),Signs!A:C,3) -> Cancer | I10: 67
A11: Samuel Little | B11: United States | C11: 1970 | D11: 2005 | E11: =Table1[[#This Row],[End year]]-Table1[[#This Row],[Starting year]] -> 35 | F11: 14769 | G11: M | H11: =VLOOKUP(DATE(2023,MONTH(F11),DAY(F11)),Signs!A:C,3) -> Gemini | I11: 60
A12: Giuseppe Greco | B12: Italy | C12: 1981 | D12: 1983 | E12: =Table1[[#This Row],[End year]]-Table1[[#This Row],[Starting year]] -> 2 | F12: 18997 | G12: M | H12: =VLOOKUP(DATE(2023,MONTH(F12),DAY(F12)),Signs!A:C,3) -> Capricorn | I12: 58
A13: Andrei Chikatilo | B13: Russia | C13: 1978 | D13: 1990 | E13: =Table1[[#This Row],[End year]]-Table1[[#This Row],[Starting year]] -> 12 | F13: 13439 | G13: M | H13: =VLOOKUP(DATE(2023,MONTH(F13),DAY(F13)),Signs!A:C,3) -> Libra | I13: 53
A14: Anatoly Onoprienko | B14: Ukraine | C14: 1989 | D14: 1996 | E14: =Table1[[#This Row],[End year]]-Table1[[#This Row],[Starting year]] -> 7 | F14: 25409 | G14: M | H14: =VLOOKUP(DATE(2023,MONTH(F14),DAY(F14)),Signs!A:C,3) -> Leo | I14: 52
A15: Ivan Maleshoff | B15: Russia | C15: 1934 | D15: 1935 | E15: =Table1[[#This Row],[End year]]-Table1[[#This Row],[Starting year]] -> 1 | F15: Unknown | G15: M | H15: Unknown | I15: 50
A16: Florisvaldo de Oliveira | B16: Brazil | C16: 1982 | D16: 1982 | E16: =Table1[[#This Row],[End year]]-Table1[[#This Row],[Starting year]] -> 0 | F16: 21507 | G16: M | H16: =VLOOKUP(DATE(2023,MONTH(F16),DAY(F16)),Signs!A:C,3) -> Scorpio | I16: 50
A17: Willy Pickton | B17: Canada | C17: 1983 | D17: 2002 | E17: =Table1[[#This Row],[End year]]-Table1[[#This Row],[Starting year]] -> 19 | F17: 18195 | G17: M | H17: =VLOOKUP(DATE(2023,MONTH(F17),DAY(F17)),Signs!A:C,3) -> Scorpio | I17: 49
A18: Gary Ridgway | B18: United States | C18: 1982 | D18: 2000 | E18: =Table1[[#This Row],[End year]]-Table1[[#This Row],[Starting year]] -> 18 | F18: 17947 | G18: M | H18: =VLOOKUP(DATE(2023,MONTH(F18),DAY(F18)),Signs!A:C,3) -> Aquarius | I18: 49
A19: Alexander Pichushkin | B19: Russia | C19: 1992 | D19: 2006 | E19: =Table1[[#This Row],[End year]]-Table1[[#This Row],[Starting year]] -> 14 | F19: 27128 | G19: M | H19: =VLOOKUP(DATE(2023,MONTH(F19),DAY(F19)),Signs!A:C,3) -> Aries | I19: 48
A20: Wang Qiang | B20: China | C20: 1995 | D20: 2003 | E20: =Table1[[#This Row],[End year]]-Table1[[#This Row],[Starting year]] -> 8 | F20: 27410 | G20: M | H20: =VLOOKUP(DATE(2023,MONTH(F20),DAY(F20)),Signs!A:C,3) -> Capricorn | I20: 45
A21: Ahmad Suradji | B21: Indonesia | C21: 1986 | D21: 1997 | E21: =Table1[[#This Row],[End year]]-Table1[[#This Row],[Starting year]] -> 11 | F21: 17908 | G21: M | H21: =VLOOKUP(DATE(2023,MONTH(F21),DAY(F21)),Signs!A:C,3) -> Capricorn | I21: 42
A22: Raman Raghav | B22: India | C22: 1965 | D22: 1968 | E22: =Table1[[#This Row],[End year]]-Table1[[#This Row],[Starting year]] -> 3 | F22: Unknown | G22: M | H22: Unknown | I22: 41
A23: Tiago Henrique Gomes da Rocha | B23: Brazil | C23: 2011 | D23: 2014 | E23: =Table1[[#This Row],[End year]]-Table1[[#This Row],[Starting year]] -> 3 | F23: 32177 | G23: M | H23: =VLOOKUP(DATE(2023,MONTH(F23),DAY(F23)),Signs!A:C,3) -> Aquarius | I23: 39
A24: Moses Sithole | B24: South Africa | C24: 1994 | D24: 1995 | E24: =Table1[[#This Row],[End year]]-Table1[[#This Row],[Starting year]] -> 1 | F24: 23698 | G24: M | H24: =VLOOKUP(DATE(2023,MONTH(F24),DAY(F24)),Signs!A:C,3) -> Scorpio | I24: 38
A25: Serhiy Tkach | B25: Russia | C25: 1984 | D25: 2005 | E25: =Table1[[#This Row],[End year]]-Table1[[#This Row],[Starting year]] -> 21 | F25: 19252 | G25: M | H25: =VLOOKUP(DATE(2023,MONTH(F25),DAY(F25)),Signs!A:C,3) -> Virgo | I25: 36
A26: Gennady Mikhasevich | B26: Russia | C26: 1971 | D26: 1985 | E26: =Table1[[#This Row],[End year]]-Table1[[#This Row],[Starting year]] -> 14 | F26: 17264 | G26: M | H26: =VLOOKUP(DATE(2023,MONTH(F26),DAY(F26)),Signs!A:C,3) -> Aries | I26: 36
A27: Hadj Mohammed Mesfewi | B27: Morocco | C27: 1906 | D27: 1906 | E27: =Table1[[#This Row],[End year]]-Table1[[#This Row],[Starting year]] -> 0 | F27: Unknown | G27: M | H27: Unknown | I27: 36
A28: Vera Renczi | B28: Kingdom of Romania | C28: 1920 | D28: 1930 | E28: =Table1[[#This Row],[End year]]-Table1[[#This Row],[Starting year]] -> 10 | F28: Unknown | G28: F | H28: Unknown | I28: 35
A29: Ted Bundy | B29: United States | C29: 1974 | D29: 1978 | E29: =Table1[[#This Row],[End year]]-Table1[[#This Row],[Starting year]] -> 4 | F29: 17130 | G29: M | H29: =VLOOKUP(DATE(2023,MONTH(F29),DAY(F29)),Signs!A:C,3) -> Sagittarius | I29: 35
A30: Clementine Barnabet | B30: United States | C30: 1911 | D30: 1911 | E30: =Table1[[#This Row],[End year]]-Table1[[#This Row],[Starting year]] -> 0 | F30: Unknown | G30: F | H30: Unknown | I30: 35
A31: John Wayne Gacy | B31: United States | C31: 1972 | D31: 1978 | E31: =Table1[[#This Row],[End year]]-Table1[[#This Row],[Starting year]] -> 6 | F31: 15417 | G31: M | H31: =VLOOKUP(DATE(2023,MONTH(F31),DAY(F31)),Signs!A:C,3) -> Pisces | I31: 33
A32: Ali Asghar Borujerdi | B32: Iran | C32: 1907 | D32: 1934 | E32: =Table1[[#This Row],[End year]]-Table1[[#This Row],[Starting year]] -> 27 | F32: Unknown | G32: M | H32: Unknown | I32: 33
A33: Vasili Komaroff | B33: Russia | C33: 1921 | D33: 1923 | E33: =Table1[[#This Row],[End year]]-Table1[[#This Row],[Starting year]] -> 2 | F33: 44927 | G33: M | H33: =VLOOKUP(DATE(2023,MONTH(F33),DAY(F33)),Signs!A:C,3) -> Capricorn | I33: 33
A34: Fernando Hernández Leyva | B34: Mexico | C34: 1982 | D34: 1999 | E34: =Table1[[#This Row],[End year]]-Table1[[#This Row],[Starting year]] -> 17 | F34: 23711 | G34: M | H34: =VLOOKUP(DATE(2023,MONTH(F34),DAY(F34)),Signs!A:C,3) -> Sagittarius | I34: 33
A35: Ramadan Abdel Rehim Mansour | B35: Egypt | C35: 1999 | D35: 2006 | E35: =Table1[[#This Row],[End year]]-Table1[[#This Row],[Starting year]] -> 7 | F35: Unknown | G35: M | H35: Unknown | I35: 32
A36: Radik Tagirov | B36: Russia | C36: 2011 | D36: 2012 | E36: =Table1[[#This Row],[End year]]-Table1[[#This Row],[Starting year]] -> 1 | F36: 34059 | G36: M | H36: =VLOOKUP(DATE(2023,MONTH(F36),DAY(F36)),Signs!A:C,3) -> Aries | I36: 32
A37: Karl Denke | B37: Germany | C37: 1900 | D37: 1924 | E37: =Table1[[#This Row],[End year]]-Table1[[#This Row],[Starting year]] -> 24 | F37: 44968 | G37: M | H37: =VLOOKUP(DATE(2023,MONTH(F37),DAY(F37)),Signs!A:C,3) -> Aquarius | I37: 30
A38: Francisco das Chagas Rodrigues de Brito | B38: Brazil | C38: 1989 | D38: 2003 | E38: =Table1[[#This Row],[End year]]-Table1[[#This Row],[Starting year]] -> 14 | F38: Unknown | G38: M | H38: Unknown | I38: 30
A39: Luis Gregorio Ramírez Maestre | B39: Colombia | C39: 2010 | D39: 2013 | E39: =Table1[[#This Row],[End year]]-Table1[[#This Row],[Starting year]] -> 3 | F39: 29494 | G39: M | H39: =VLOOKUP(DATE(2023,MONTH(F39),DAY(F39)),Signs!A:C,3) -> Libra | I39: 30
A40: David Thabo Simelane | B40: Swaziland | C40: 2000 | D40: 2001 | E40: =Table1[[#This Row],[End year]]-Table1[[#This Row],[Starting year]] -> 1 | F40: Unknown | G40: M | H40: Unknown | I40: 28
...

Sheet Comparisons
B1: Zodiac of the killer | C1: Amount of killers
B2: Unknown | C2: =COUNTIF(Data!H:H,B2) -> 83
B3: Capricorn | C3: =COUNTIF(Data!H:H,B3) -> 24
B4: Pisces | C4: =COUNTIF(Data!H:H,B4) -> 24
B5: Scorpio | C5: =COUNTIF(Data!H:H,B5) -> 24
B6: Sagittarius | C6: =COUNTIF(Data!H:H,B6) -> 23
B7: Aries | C7: =COUNTIF(Data!H:H,B7) -> 21
B8: Aquarius | C8: =COUNTIF(Data!H:H,B8) -> 20
B9: Cancer | C9: =COUNTIF(Data!H:H,B9) -> 20
B10: Taurus | C10: =COUNTIF(Data!H:H,B10) -> 17
B11: Gemini | C11: =COUNTIF(Data!H:H,B11) -> 17
B12: Libra | C12: =COUNTIF(Data!H:H,B12) -> 14
B13: Virgo | C13: =COUNTIF(Data!H:H,B13) -> 12
B14: Leo | C14: =COUNTIF(Data!H:H,B14) -> 10
B17: Gender of the killer | C17: Amount
B18: M | C18: =COUNTIF(Data!G:G,B18) -> 274
B19: F | C19: =COUNTIF(Data!G:G,B19) -> 19
B20: U | C20: =COUNTIF(Data!G:G,B20) -> 16
B23: Zodiac of the killer | C23: Proven Victims
B24: Unknown | C24: =SUMIF(Table1[Zodiac sign],B24,Table1[Proven victims]) -> 1518
B25: Aquarius | C25: =SUMIF(Table1[Zodiac sign],B25,Table1[Proven victims]) -> 574
B26: Scorpio | C26: =SUMIF(Table1[Zodiac sign],B26,Table1[Proven victims]) -> 446
B27: Capricorn | C27: =SUMIF(Table1[Zodiac sign],B27,Table1[Proven victims]) -> 401
B28: Pisces | C28: =SUMIF(Table1[Zodiac sign],B28,Table1[Proven victims]) -> 365
B29: Aries | C29: =SUMIF(Table1[Zodiac sign],B29,Table1[Proven victims]) -> 331
B30: Libra | C30: =SUMIF(Table1[Zodiac sign],B30,Table1[Proven victims]) -> 315
B31: Sagittarius | C31: =SUMIF(Table1[Zodiac sign],B31,Table1[Proven victims]) -> 294
B32: Cancer | C32: =SUMIF(Table1[Zodiac sign],B32,Table1[Proven victims]) -> 251
B33: Gemini | C33: =SUMIF(Table1[Zodiac sign],B33,Table1[Proven victims]) -> 226
B34: Taurus | C34: =SUMIF(Table1[Zodiac sign],B34,Table1[Proven victims]) -> 196
B35: Leo | C35: =SUMIF(Table1[Zodiac sign],B35,Table1[Proven victims]) -> 176
B36: Virgo | C36: =SUMIF(Table1[Zodiac sign],B36,Table1[Proven victims]) -> 132
B39: Country of origin | C39: Count of killers
B40: United States | C40: =COUNTIF(Data!B:B,B40) -> 96
B41: Russia | C41: =COUNTIF(Data!B:B,B41) -> 40
B42: South Africa | C42: =COUNTIF(Data!B:B,B42) -> 19
B43: United Kingdom | C43: =COUNTIF(Data!B:B,B43) -> 13
B44: India | C44: =COUNTIF(Data!B:B,B44) -> 10
B45: China | C45: =COUNTIF(Data!B:B,B45) -> 9
B46: Brazil | C46: =COUNTIF(Data!B:B,B46) -> 8
...

Sheet Signs
A1: 44927 | B1: 44945 | C1: Capricorn
A2: 44946 | B2: 44975 | C2: Aquarius
A3: 44976 | B3: 45005 | C3: Pisces
A4: 45006 | B4: 45035 | C4: Aries
A5: 45036 | B5: 45066 | C5: Taurus
A6: 45067 | B6: 45097 | C6: Gemini
A7: 45098 | B7: 45129 | C7: Cancer
A8: 45130 | B8: 45160 | C8: Leo
A9: 45161 | B9: 45191 | C9: Virgo
A10: 45192 | B10: 45222 | C10: Libra
A11: 45223 | B11: 45251 | C11: Scorpio
A12: 45252 | B12: 45281 | C12: Sagittarius
A13: 45282 | B13: 45290 | C13: Capricorn
